<?xml version="1.0"?>
<robot name="four_wheel_robot" xmlns:xacro="http://www.ros.org/wiki/xacro">


    <!--MATERIALS-->
    <material name="cyan_green">
        <color rgba="0.47 0.65 0.64 1"/>
    </material>    

    <material name="dark_grey">
        <color rgba="0.37 0.37 0.35 1"/>
    </material>
    <material name="white">
        <color rgba="1 1 1 1"/>
    </material>
    

    <!--LINKS-->
    <!--base_link-->
    <link name="base_link">
        <visual>
            <geometry>
                <box size="0.6 0.4 0.2"/>
            </geometry>
            <origin xyz="0 0 0.1" rpy="0 0 0"/>
            <material name="cyan_green"/>
        </visual>
        <collision>
            <geometry>
                <box size="0.6 0.4 0.2"/>
            </geometry>
            <origin xyz="0 0 0.1" rpy="0 0 0"/>
        </collision>
        <inertial>
            <origin xyz="0 0 0.1" rpy="0 0 0"/>
            <mass value="5.0"/> <!-- ~5kg chassis -->
            <inertia ixx="0.08" ixy="0.0" ixz="0.0" iyy="0.05" iyz="0.0" izz="0.08"/>
        </inertial>
    </link>

    <!--wheels-->  
    <xacro:macro name="wheel_link" params="prefix">
        <link name="${prefix}_wheel">
            <visual>
                <geometry>
                    <cylinder radius="0.1" length="0.05"/>
                </geometry>
                <origin xyz="0 0 0" rpy="1.57 0 0"/>
                <material name="dark_grey"/>
            </visual>
            <collision>
                <geometry>
                    <cylinder radius="0.1" length="0.05"/>
                </geometry>
                <origin xyz="0 0 0" rpy="1.57 0 0"/>
            </collision>
            <inertial>
                <origin xyz="0 0 0" rpy="1.57 0 0"/>
                <mass value="0.5"/> <!-- ~0.5kg per wheel -->
                <inertia ixx="0.0025" ixy="0.0" ixz="0.0" iyy="0.0025" iyz="0.0" izz="0.005"/>
            </inertial>
        </link>
    </xacro:macro>

    <xacro:wheel_link prefix="left_back"/>
    <xacro:wheel_link prefix="right_back"/>
    <xacro:wheel_link prefix="left_front"/>
    <xacro:wheel_link prefix="right_front"/>

    <!--lidar-->
    <link name="lidar_link">

        <visual>
            <geometry>
                <cylinder radius="0.1" length="0.05"/>
            </geometry>
            <origin xyz="0 0 0" rpy="0 0 0"/>
            <material name="white"/>
        </visual>
        <collision>
            <geometry>
                <cylinder radius="0.1" length="0.05"/>
            </geometry>
            <origin xyz="0 0 0" rpy="0 0 0"/>
        </collision>
        <inertial>
            <origin xyz="0 0 0" rpy="0 0 0"/>
            <mass value="0.2"/> <!-- ~200g LIDAR -->
            <inertia ixx="0.0005" ixy="0.0" ixz="0.0" iyy="0.0005" iyz="0.0" izz="0.0001"/>
        </inertial>
    </link>
  
    <!--camera-->
    <link name="camera_link">
        <visual>
            <geometry>
                <box size="0.05 0.15 0.1"/>
            </geometry>
            <origin xyz="0 0 0" rpy="0 0 0"/>
            <material name="white"/>
        </visual>
        <collision>
            <geometry>
                <box size="0.15 0.1 0.05"/>
            </geometry>
            <origin xyz="0 0 0" rpy="0 0 0"/>
        </collision>
        <inertial>
            <mass value="0.2"/>
            <inertia
                ixx="0.000416667" ixy="0.0" ixz="0.0"
                iyy="0.000416667" iyz="0.0"
                izz="0.000416667"/>
        </inertial>
    </link>
   
    

   
    <!--JOINTS-->
    <!--base_wheel-->
    <xacro:macro name="wheel_joint" params="prefix lr fb">
        <joint name="base_${prefix}_wheel_joint" type="continuous">
            <parent link="base_link"/>
            <child link="${prefix}_wheel"/>
            <origin xyz="${fb} ${lr} 0" rpy="0 0 0"/>
            <axis xyz="0 1 0"/>
        </joint>
    </xacro:macro>

    <xacro:wheel_joint prefix="left_back" lr="0.225" fb="-0.15"/>
    <xacro:wheel_joint prefix="right_back" lr="-0.225" fb="-0.15"/>
    <xacro:wheel_joint prefix="left_front" lr="0.225" fb="0.15"/>
    <xacro:wheel_joint prefix="right_front" lr="-0.225" fb="0.15"/>

    <!--base_lidar-->
    <joint name="base_lidar_joint" type="fixed">
        <parent link="base_link"/>
        <child link="lidar_link"/>
        <origin xyz="0.15 0 0.225" rpy="0 0 0"/>
    </joint>

    <!--lidar_camera-->
    <joint name="lidar_camera_joint" type="fixed">
        <parent link="lidar_link"/>
        <child link="camera_link"/>
        <origin xyz="0 0 0.075" rpy="0 0 0"/>
    </joint>

    <!--GAZEBO_MATERIALS-->
    <gazebo reference="base_link">
        <material>Gazebo/Cyan</material>
    </gazebo>
    <gazebo reference="wheel_link">
        <material>Gazebo/Grey</material>
    </gazebo>
    <gazebo reference="lidar_link">
        <material>Gazebo/White</material>
    </gazebo>
    <gazebo reference="camera_link">
        <material>Gazebo/White</material>
    </gazebo>

    <!--GAZEBO_PLUGINS-->
    <!--diff_drive_plugin-->
    <gazebo>
        <plugin name="differential_drive_controller" filename="libgazebo_ros_diff_drive.so">
            <ros>
            <remapping>cmd_vel:=/cmd_vel</remapping>
            <remapping>odom:=/odom</remapping>
            </ros>
            <left_joint>base_left_back_wheel_joint</left_joint>
            <right_joint>base_right_back_wheel_joint</right_joint>
            <wheel_separation>0.45</wheel_separation> <!-- Distance between left and right wheels -->
            <wheel_diameter>0.2</wheel_diameter>       <!-- Based on your cylinder radius of 0.1 -->
            <robot_base_frame>base_link</robot_base_frame>
            <odometry_frame>odom</odometry_frame>
            <odometry_topic>odom</odometry_topic>
            <command_topic>cmd_vel</command_topic>
            <publish_odom>true</publish_odom>
            <publish_odom_tf>true</publish_odom_tf>
            <publish_wheel_tf>true</publish_wheel_tf>
            <update_rate>50</update_rate>
        </plugin>
    </gazebo>
    <!--lidar_plugin-->
   <gazebo reference="lidar_link">
        <sensor name="lidar" type="ray">
            <pose>0 0 0 0 0 0</pose>
            <update_rate>10</update_rate>
            <!--<visualize>true</visualize>-->

            <ray>
            <scan>
                <horizontal>
                <samples>360</samples>             <!-- 1° resolution -->
                <resolution>1.0</resolution>
                <min_angle>-3.14159</min_angle>    <!-- -π = -180° -->
                <max_angle>3.14159</max_angle>     <!-- π = +180° -->
                </horizontal>
            </scan>

            <range>
                <min>0.12</min>                      <!-- realistic for RPLiDAR -->
                <max>6.0</max>                       <!-- 6 meters max range -->
                <resolution>0.01</resolution>
            </range>
            </ray>

            <plugin name="gazebo_ros_laser_controller" filename="libgazebo_ros_ray_sensor.so">
            <ros>
                <remapping>scan:=scan</remapping>
            </ros>
            <frame_name>lidar_link</frame_name>
            </plugin>
        </sensor>
    </gazebo>
    <!--camera_plugin-->
    <gazebo reference="camera_link">
        <sensor type="camera" name="camera">
            <always_on>true</always_on>
            <update_rate>30.0</update_rate>
            <visualize>true</visualize> 
            <camera>
            <horizontal_fov>1.047</horizontal_fov>  <!-- 60 degrees -->
            <image>
                <width>640</width>
                <height>480</height>
                <format>R8G8B8</format>
            </image>
            <clip>
                <near>0.1</near>
                <far>100.0</far>
            </clip>
            </camera>
            <plugin name="camera_plugin" filename="libgazebo_ros_camera.so">
            <ros>
                <namespace>/camera</namespace>
            </ros>
            <camera_name>camera</camera_name>
            <frame_name>camera_link</frame_name>
            </plugin>
        </sensor>
    </gazebo>


    
</robot>